Workbook

Sheet Cadastro
A1: Cód SKU | B1: Descrição | C1: Linha | D1: Rendim. | E1: Cód Subgrupo | F1: Descrição Subgrupo | G1: Litragem | H1: Subgrupo Litragem
A2: 20010001 | B2: Agua Sanitaria Aquafast Cx/12 X 1l | C2: Ln 01 | D2: 350 | E2: 1 | F2: AGUA SANITARIA | G2: 1 LITRO | H2: =CONCATENATE(F2," ",G2) -> AGUA SANITARIA 1 LITRO
A3: 20010002 | B3: Agua Sanitaria Aquafast Cx/06 X 2l | C3: Ln 01 | D3: 650 | E3: 1 | F3: AGUA SANITARIA | G3: 2 LITROS | H3: =CONCATENATE(F3," ",G3) -> AGUA SANITARIA 2 LITROS
A4: 20010003 | B4: Agua Sanitaria Aquafast Cx/04 X 5l | C4: Ln 02 | D4: 560 | E4: 1 | F4: AGUA SANITARIA | G4: 5 LITROS | H4: =CONCATENATE(F4," ",G4) -> AGUA SANITARIA 5 LITROS
A5: 20010011 | B5: Agua Sanitaria Verde Ito Cx/04 X 5l | C5: Ln 02 | D5: 560 | E5: 1 | F5: AGUA SANITARIA | G5: 5 LITROS | H5: =CONCATENATE(F5," ",G5) -> AGUA SANITARIA 5 LITROS
A6: 20010017 | B6: Agua Sanitaria Verde Ito Cx/12 X 1l | C6: Ln 01 | D6: 350 | E6: 1 | F6: AGUA SANITARIA | G6: 1 LITRO | H6: =CONCATENATE(F6," ",G6) -> AGUA SANITARIA 1 LITRO
A7: 20010018 | B7: Agua Sanitaria Verde Ito Cx/06 X 2l | C7: Ln 01 | D7: 650 | E7: 1 | F7: AGUA SANITARIA | G7: 2 LITROS | H7: =CONCATENATE(F7," ",G7) -> AGUA SANITARIA 2 LITROS
A8: 20010022 | B8: Agua Sanitaria Myata Cx/12 X 1l | C8: Ln 01 | D8: 350 | E8: 1 | F8: AGUA SANITARIA | G8: 1 LITRO | H8: =CONCATENATE(F8," ",G8) -> AGUA SANITARIA 1 LITRO
A9: 20010023 | B9: Agua Sanitaria Myata Cx/06 X 2l | C9: Ln 01 | D9: 650 | E9: 1 | F9: AGUA SANITARIA | G9: 2 LITROS | H9: =CONCATENATE(F9," ",G9) -> AGUA SANITARIA 2 LITROS
A10: 20030001 | B10: Detergente Aquafast Maca Cx/24 X 500ml | C10: Ln 04 | D10: 275 | E10: 3 | F10: DETERGENTE | G10: 500 ML | H10: =CONCATENATE(F10," ",G10) -> DETERGENTE 500 ML
A11: 20030002 | B11: Detergente Aquafast Limao Cx/24 X 500ml | C11: Ln 04 | D11: 275 | E11: 3 | F11: DETERGENTE | G11: 500 ML | H11: =CONCATENATE(F11," ",G11) -> DETERGENTE 500 ML
A12: 20030003 | B12: Detergente Aquafast Neutro Cx/24 X 500ml | C12: Ln 04 | D12: 275 | E12: 3 | F12: DETERGENTE | G12: 500 ML | H12: =CONCATENATE(F12," ",G12) -> DETERGENTE 500 ML
A13: 20030004 | B13: Detergente Aquafast Clear Cx/24 X 500ml (Natural) | C13: Ln 04 | D13: 275 | E13: 3 | F13: DETERGENTE | G13: 500 ML | H13: =CONCATENATE(F13," ",G13) -> DETERGENTE 500 ML
... A175: 20280001 | B175: Promopack Desinfetante Aquafast Cx C/4pack C/3un X 1l | C175: Ln 10 | D175: 50 | E175: 28 | F175: DESINFETANTE PACK | G175: 1 LITRO | H175: =CONCATENATE(F175," ",G175) -> DESINFETANTE PACK 1 LITRO

Sheet Linha 01
A1: Coluna1 | B1: Coluna2 | C1: Coluna3 | D1: Coluna4 | E1: Coluna5 | F1: Coluna6 | G1: Coluna7 | H1: Coluna8 | I1: Coluna9 | J1: Coluna10
C2: Agua Sanitaria Aquafast Cx/12 X 1l | D2: Agua Sanitaria Aquafast Cx/06 X 2l | E2: Agua Sanitaria Verde Ito Cx/12 X 1l | F2: Agua Sanitaria Verde Ito Cx/06 X 2l | G2: Agua Sanitaria Myata Cx/12 X 1l | H2: Agua Sanitaria Myata Cx/06 X 2l | I2: Alvejante S/ Cloro Aquafast Cx/12 X 1l | J2: Alvejante S/ Cloro Aquafast Cx/06 X 2l
C3: 20010001 | D3: 20010002 | E3: 20010017 | F3: 20010018 | G3: 20010022 | H3: 20010023 | I3: 20160001 | J3: 20160002
A4: 20010001 | B4: Agua Sanitaria Aquafast Cx/12 X 1l | C4: 0 | D4: 0.034722222 | E4: 0 | F4: 0.034722222 | G4: 0 | H4: 0.034722222 | I4: 0.013888889 | J4: 0.034722222
A5: 20010002 | B5: Agua Sanitaria Aquafast Cx/06 X 2l | C5: 0.034722222 | D5: 0 | E5: 0.034722222 | F5: 0 | G5: 0.034722222 | H5: 0 | I5: 0.034722222 | J5: 0.013888889
A6: 20010017 | B6: Agua Sanitaria Verde Ito Cx/12 X 1l | C6: 0 | D6: 0.034722222 | E6: 0 | F6: 0.034722222 | G6: 0 | H6: 0.034722222 | I6: 0.013888889 | J6: 0.034722222
A7: 20010018 | B7: Agua Sanitaria Verde Ito Cx/06 X 2l | C7: 0.034722222 | D7: 0 | E7: 0.034722222 | F7: 0 | G7: 0.034722222 | H7: 0 | I7: 0.034722222 | J7: 0.013888889
A8: 20010022 | B8: Agua Sanitaria Myata Cx/12 X 1l | C8: 0 | D8: 0.034722222 | E8: 0 | F8: 0.034722222 | G8: 0 | H8: 0.034722222 | I8: 0.013888889 | J8: 0.034722222
A9: 20010023 | B9: Agua Sanitaria Myata Cx/06 X 2l | C9: 0.034722222 | D9: 0 | E9: 0.034722222 | F9: 0 | G9: 0.034722222 | H9: 0 | I9: 0.034722222 | J9: 0.013888889
A10: 20160001 | B10: Alvejante S/ Cloro Aquafast Cx/12 X 1l | C10: 0.013888889 | D10: 0.034722222 | E10: 0.013888889 | F10: 0.034722222 | G10: 0.013888889 | H10: 0.034722222 | I10: 0 | J10: 0.034722222
A11: 20160002 | B11: Alvejante S/ Cloro Aquafast Cx/06 X 2l | C11: 0.034722222 | D11: 0.013888889 | E11: 0.034722222 | F11: 0.013888889 | G11: 0.034722222 | H11: 0.013888889 | I11: 0.034722222 | J11: 0

Sheet LISTA 01
A1: =COUNTA('Linha 01'!B:B)-1 -> 8 | B1: =COUNTA('Linha 01'!2:2) -> 8 | C1: =A1*B1 -> 64
A3: {=_xlfn.SEQUENCE($C$1)} -> 1 | B3: =INT((A3-1)/$B$1)+1 -> 1 | C3: =MOD(A3-1,$B$1)+1 -> 1 | D3: {=INDEX('Linha 01'!$A$4:$A$1000,B3)} -> 20010001 | E3: {=INDEX('Linha 01'!$B$4:$B$1000,B3)} -> Agua Sanitaria Aquafast Cx/12 X 1l | F3: {=INDEX('Linha 01'!$C$3:$Z$3,C3)} -> 20010001 | G3: {=INDEX('Linha 01'!$C$2:$Z$2,C3)} -> Agua Sanitaria Aquafast Cx/12 X 1l | H3: {=INDEX('Linha 01'!$C$4:$ZZ$1000,B3,C3)} -> 0
A4: 2 | B4: =INT((A4-1)/$B$1)+1 -> 1 | C4: =MOD(A4-1,$B$1)+1 -> 2 | D4: {=INDEX('Linha 01'!$A$4:$A$1000,B4)} -> 20010001 | E4: {=INDEX('Linha 01'!$B$4:$B$1000,B4)} -> Agua Sanitaria Aquafast Cx/12 X 1l | F4: {=INDEX('Linha 01'!$C$3:$Z$3,C4)} -> 20010002 | G4: {=INDEX('Linha 01'!$C$2:$Z$2,C4)} -> Agua Sanitaria Aquafast Cx/06 X 2l | H4: {=INDEX('Linha 01'!$C$4:$ZZ$1000,B4,C4)} -> 0.034722222
A5: 3 | B5: =INT((A5-1)/$B$1)+1 -> 1 | C5: =MOD(A5-1,$B$1)+1 -> 3 | D5: {=INDEX('Linha 01'!$A$4:$A$1000,B5)} -> 20010001 | E5: {=INDEX('Linha 01'!$B$4:$B$1000,B5)} -> Agua Sanitaria Aquafast Cx/12 X 1l | F5: {=INDEX('Linha 01'!$C$3:$Z$3,C5)} -> 20010017 | G5: {=INDEX('Linha 01'!$C$2:$Z$2,C5)} -> Agua Sanitaria Verde Ito Cx/12 X 1l | H5: {=INDEX('Linha 01'!$C$4:$ZZ$1000,B5,C5)} -> 0
A6: 4 | B6: =INT((A6-1)/$B$1)+1 -> 1 | C6: =MOD(A6-1,$B$1)+1 -> 4 | D6: {=INDEX('Linha 01'!$A$4:$A$1000,B6)} -> 20010001 | E6: {=INDEX('Linha 01'!$B$4:$B$1000,B6)} -> Agua Sanitaria Aquafast Cx/12 X 1l | F6: {=INDEX('Linha 01'!$C$3:$Z$3,C6)} -> 20010018 | G6: {=INDEX('Linha 01'!$C$2:$Z$2,C6)} -> Agua Sanitaria Verde Ito Cx/06 X 2l | H6: {=INDEX('Linha 01'!$C$4:$ZZ$1000,B6,C6)} -> 0.034722222
A7: 5 | B7: =INT((A7-1)/$B$1)+1 -> 1 | C7: =MOD(A7-1,$B$1)+1 -> 5 | D7: {=INDEX('Linha 01'!$A$4:$A$1000,B7)} -> 20010001 | E7: {=INDEX('Linha 01'!$B$4:$B$1000,B7)} -> Agua Sanitaria Aquafast Cx/12 X 1l | F7: {=INDEX('Linha 01'!$C$3:$Z$3,C7)} -> 20010022 | G7: {=INDEX('Linha 01'!$C$2:$Z$2,C7)} -> Agua Sanitaria Myata Cx/12 X 1l | H7: {=INDEX('Linha 01'!$C$4:$ZZ$1000,B7,C7)} -> 0
A8: 6 | B8: =INT((A8-1)/$B$1)+1 -> 1 | C8: =MOD(A8-1,$B$1)+1 -> 6 | D8: {=INDEX('Linha 01'!$A$4:$A$1000,B8)} -> 20010001 | E8: {=INDEX('Linha 01'!$B$4:$B$1000,B8)} -> Agua Sanitaria Aquafast Cx/12 X 1l | F8: {=INDEX('Linha 01'!$C$3:$Z$3,C8)} -> 20010023 | G8: {=INDEX('Linha 01'!$C$2:$Z$2,C8)} -> Agua Sanitaria Myata Cx/06 X 2l | H8: {=INDEX('Linha 01'!$C$4:$ZZ$1000,B8,C8)} -> 0.034722222
A9: 7 | B9: =INT((A9-1)/$B$1)+1 -> 1 | C9: =MOD(A9-1,$B$1)+1 -> 7 | D9: {=INDEX('Linha 01'!$A$4:$A$1000,B9)} -> 20010001 | E9: {=INDEX('Linha 01'!$B$4:$B$1000,B9)} -> Agua Sanitaria Aquafast Cx/12 X 1l | F9: {=INDEX('Linha 01'!$C$3:$Z$3,C9)} -> 20160001 | G9: {=INDEX('Linha 01'!$C$2:$Z$2,C9)} -> Alvejante S/ Cloro Aquafast Cx/12 X 1l | H9: {=INDEX('Linha 01'!$C$4:$ZZ$1000,B9,C9)} -> 0.013888889
A10: 8 | B10: =INT((A10-1)/$B$1)+1 -> 1 | C10: =MOD(A10-1,$B$1)+1 -> 8 | D10: {=INDEX('Linha 01'!$A$4:$A$1000,B10)} -> 20010001 | E10: {=INDEX('Linha 01'!$B$4:$B$1000,B10)} -> Agua Sanitaria Aquafast Cx/12 X 1l | F10: {=INDEX('Linha 01'!$C$3:$Z$3,C10)} -> 20160002 | G10: {=INDEX('Linha 01'!$C$2:$Z$2,C10)} -> Alvejante S/ Cloro Aquafast Cx/06 X 2l | H10: {=INDEX('Linha 01'!$C$4:$ZZ$1000,B10,C10)} -> 0.034722222
A11: 9 | B11: =INT((A11-1)/$B$1)+1 -> 2 | C11: =MOD(A11-1,$B$1)+1 -> 1 | D11: {=INDEX('Linha 01'!$A$4:$A$1000,B11)} -> 20010002 | E11: {=INDEX('Linha 01'!$B$4:$B$1000,B11)} -> Agua Sanitaria Aquafast Cx/06 X 2l | F11: {=INDEX('Linha 01'!$C$3:$Z$3,C11)} -> 20010001 | G11: {=INDEX('Linha 01'!$C$2:$Z$2,C11)} -> Agua Sanitaria Aquafast Cx/12 X 1l | H11: {=INDEX('Linha 01'!$C$4:$ZZ$1000,B11,C11)} -> 0.034722222
A12: 10 | B12: =INT((A12-1)/$B$1)+1 -> 2 | C12: =MOD(A12-1,$B$1)+1 -> 2 | D12: {=INDEX('Linha 01'!$A$4:$A$1000,B12)} -> 20010002 | E12: {=INDEX('Linha 01'!$B$4:$B$1000,B12)} -> Agua Sanitaria Aquafast Cx/06 X 2l | F12: {=INDEX('Linha 01'!$C$3:$Z$3,C12)} -> 20010002 | G12: {=INDEX('Linha 01'!$C$2:$Z$2,C12)} -> Agua Sanitaria Aquafast Cx/06 X 2l | H12: {=INDEX('Linha 01'!$C$4:$ZZ$1000,B12,C12)} -> 0
A13: 11 | B13: =INT((A13-1)/$B$1)+1 -> 2 | C13: =MOD(A13-1,$B$1)+1 -> 3 | D13: {=INDEX('Linha 01'!$A$4:$A$1000,B13)} -> 20010002 | E13: {=INDEX('Linha 01'!$B$4:$B$1000,B13)} -> Agua Sanitaria Aquafast Cx/06 X 2l | F13: {=INDEX('Linha 01'!$C$3:$Z$3,C13)} -> 20010017 | G13: {=INDEX('Linha 01'!$C$2:$Z$2,C13)} -> Agua Sanitaria Verde Ito Cx/12 X 1l | H13: {=INDEX('Linha 01'!$C$4:$ZZ$1000,B13,C13)} -> 0.034722222
A14: 12 | B14: =INT((A14-1)/$B$1)+1 -> 2 | C14: =MOD(A14-1,$B$1)+1 -> 4 | D14: {=INDEX('Linha 01'!$A$4:$A$1000,B14)} -> 20010002 | E14: {=INDEX('Linha 01'!$B$4:$B$1000,B14)} -> Agua Sanitaria Aquafast Cx/06 X 2l | F14: {=INDEX('Linha 01'!$C$3:$Z$3,C14)} -> 20010018 | G14: {=INDEX('Linha 01'!$C$2:$Z$2,C14)} -> Agua Sanitaria Verde Ito Cx/06 X 2l | H14: {=INDEX('Linha 01'!$C$4:$ZZ$1000,B14,C14)} -> 0
A15: 13 | B15: =INT((A15-1)/$B$1)+1 -> 2 | C15: =MOD(A15-1,$B$1)+1 -> 5 | D15: {=INDEX('Linha 01'!$A$4:$A$1000,B15)} -> 20010002 | E15: {=INDEX('Linha 01'!$B$4:$B$1000,B15)} -> Agua Sanitaria Aquafast Cx/06 X 2l | F15: {=INDEX('Linha 01'!$C$3:$Z$3,C15)} -> 20010022 | G15: {=INDEX('Linha 01'!$C$2:$Z$2,C15)} -> Agua Sanitaria Myata Cx/12 X 1l | H15: {=INDEX('Linha 01'!$C$4:$ZZ$1000,B15,C15)} -> 0.034722222
... A66: 64 | B66: =INT((A66-1)/$B$1)+1 -> 8 | C66: =MOD(A66-1,$B$1)+1 -> 8 | D66: {=INDEX('Linha 01'!$A$4:$A$1000,B66)} -> 20160002 | E66: {=INDEX('Linha 01'!$B$4:$B$1000,B66)} -> Alvejante S/ Cloro Aquafast Cx/06 X 2l | F66: {=INDEX('Linha 01'!$C$3:$Z$3,C66)} -> 20160002 | G66: {=INDEX('Linha 01'!$C$2:$Z$2,C66)} -> Alvejante S/ Cloro Aquafast Cx/06 X 2l | H66: {=INDEX('Linha 01'!$C$4:$ZZ$1000,B66,C66)} -> 0

Sheet Linha 02
A1: Coluna1 | B1: Coluna2 | C1: Coluna3 | D1: Coluna4 | E1: Coluna5 | F1: Coluna6 | G1: Coluna7 | H1: Coluna8 | I1: Coluna9 | J1: Coluna10 | K1: Coluna11 | L1: Coluna12
C2: Agua Sanitaria Aquafast Cx/04 X 5l | D2: Agua Sanitaria Verde Ito Cx/04 X 5l | E2: Desinfetante Aquafast Campos Lavanda Cx/04 5l Emb. Econ | F2: Desinfetante Aquafast Marine Cx/04 X 5l Emb. Economica | G2: Desinfetante Aquafast Paixao Cx/04 X 5l Emb. Economica | H2: Desinfetante Ito Lavanda Cx/04 X 5l | I2: Desinfetante Ito Marine Cx/04 X 5l | J2: Desinfetante Aquafast Cha Branco Cx/04 X 5l Emb. Econo | K2: Alvejante S/ Cloro Aquafast Cx/04 X 5l (Emb Econ) | L2: Alvejante S/ Cloro Aquafast Cx/04 X 3l
C3: 20010003 | D3: 20010011 | E3: 20050113 | F3: 20050114 | G3: 20050116 | H3: 20050143 | I3: 20050144 | J3: 20050158 | K3: 20160003 | L3: 20160005
A4: 20010003 | B4: Agua Sanitaria Aquafast Cx/04 X 5l | C4: 0 | D4: 0.0069444444 | E4: 0.034722222 | F4: 0.034722222 | G4: 0.010416667 | H4: 0.010416667 | I4: 0.010416667 | J4: 0.013888889 | K4: 0.0069444444 | L4: 0.0069444444
A5: 20010011 | B5: Agua Sanitaria Verde Ito Cx/04 X 5l | D5: 0 | E5: 0.034722222 | F5: 0.034722222 | J5: 0.013888889
A6: 20050113 | B6: Desinfetante Aquafast Campos Lavanda Cx/04 5l Emb. Econ | C6: 0.034722222 | D6: 0.034722222 | E6: 0 | J6: 0.013888889
A7: 20050114 | B7: Desinfetante Aquafast Marine Cx/04 X 5l Emb. Economica | C7: 0.010416667 | E7: 0.010416667 | F7: 0 | G7: 0.010416667 | J7: 0.013888889
A8: 20050116 | B8: Desinfetante Aquafast Paixao Cx/04 X 5l Emb. Economica | G8: 0 | J8: 0.013888889
A9: 20050143 | B9: Desinfetante Ito Lavanda Cx/04 X 5l | H9: 0 | J9: 0.013888889
A10: 20050144 | B10: Desinfetante Ito Marine Cx/04 X 5l | I10: 0 | J10: 0.013888889
A11: 20050158 | B11: Desinfetante Aquafast Cha Branco Cx/04 X 5l Emb. Econo | J11: 0
A12: 20160003 | B12: Alvejante S/ Cloro Aquafast Cx/04 X 5l (Emb Econ) | C12: 0.0069444444 | E12: 0.0069444444 | J12: 0.013888889 | K12: 0 | L12: 0
A13: 20160005 | B13: Alvejante S/ Cloro Aquafast Cx/04 X 3l | J13: 0.0069444444 | L13: 0

Sheet LISTA 02
A1: =COUNTA('Linha 02'!B:B)-1 -> 10 | B1: =COUNTA('Linha 02'!2:2) -> 10 | C1: =A1*B1 -> 100
A3: {=_xlfn.SEQUENCE($C$1)} -> 1 | B3: =INT((A3-1)/$B$1)+1 -> 1 | C3: =MOD(A3-1,$B$1)+1 -> 1 | D3: {=INDEX('Linha 02'!$A$4:$A$1000,B3)} -> 20010003 | E3: {=INDEX('Linha 02'!$B$4:$B$1000,B3)} -> Agua Sanitaria Aquafast Cx/04 X 5l | F3: {=INDEX('Linha 02'!$C$3:$Z$3,C3)} -> 20010003 | G3: {=INDEX('Linha 02'!$C$2:$Z$2,C3)} -> Agua Sanitaria Aquafast Cx/04 X 5l | H3: {=INDEX('Linha 02'!$C$4:$ZZ$1000,B3,C3)} -> 0
A4: 2 | B4: =INT((A4-1)/$B$1)+1 -> 1 | C4: =MOD(A4-1,$B$1)+1 -> 2 | D4: {=INDEX('Linha 02'!$A$4:$A$1000,B4)} -> 20010003 | E4: {=INDEX('Linha 02'!$B$4:$B$1000,B4)} -> Agua Sanitaria Aquafast Cx/04 X 5l | F4: {=INDEX('Linha 02'!$C$3:$Z$3,C4)} -> 20010011 | G4: {=INDEX('Linha 02'!$C$2:$Z$2,C4)} -> Agua Sanitaria Verde Ito Cx/04 X 5l | H4: {=INDEX('Linha 02'!$C$4:$ZZ$1000,B4,C4)} -> 0.0069444444
A5: 3 | B5: =INT((A5-1)/$B$1)+1 -> 1 | C5: =MOD(A5-1,$B$1)+1 -> 3 | D5: {=INDEX('Linha 02'!$A$4:$A$1000,B5)} -> 20010003 | E5: {=INDEX('Linha 02'!$B$4:$B$1000,B5)} -> Agua Sanitaria Aquafast Cx/04 X 5l | F5: {=INDEX('Linha 02'!$C$3:$Z$3,C5)} -> 20050113 | G5: {=INDEX('Linha 02'!$C$2:$Z$2,C5)} -> Desinfetante Aquafast Campos Lavanda Cx/04 5l Emb. Econ | H5: {=INDEX('Linha 02'!$C$4:$ZZ$1000,B5,C5)} -> 0.034722222
A6: 4 | B6: =INT((A6-1)/$B$1)+1 -> 1 | C6: =MOD(A6-1,$B$1)+1 -> 4 | D6: {=INDEX('Linha 02'!$A$4:$A$1000,B6)} -> 20010003 | E6: {=INDEX('Linha 02'!$B$4:$B$1000,B6)} -> Agua Sanitaria Aquafast Cx/04 X 5l | F6: {=INDEX('Linha 02'!$C$3:$Z$3,C6)} -> 20050114 | G6: {=INDEX('Linha 02'!$C$2:$Z$2,C6)} -> Desinfetante Aquafast Marine Cx/04 X 5l Emb. Economica | H6: {=INDEX('Linha 02'!$C$4:$ZZ$1000,B6,C6)} -> 0.034722222
A7: 5 | B7: =INT((A7-1)/$B$1)+1 -> 1 | C7: =MOD(A7-1,$B$1)+1 -> 5 | D7: {=INDEX('Linha 02'!$A$4:$A$1000,B7)} -> 20010003 | E7: {=INDEX('Linha 02'!$B$4:$B$1000,B7)} -> Agua Sanitaria Aquafast Cx/04 X 5l | F7: {=INDEX('Linha 02'!$C$3:$Z$3,C7)} -> 20050116 | G7: {=INDEX('Linha 02'!$C$2:$Z$2,C7)} -> Desinfetante Aquafast Paixao Cx/04 X 5l Emb. Economica | H7: {=INDEX('Linha 02'!$C$4:$ZZ$1000,B7,C7)} -> 0.010416667
A8: 6 | B8: =INT((A8-1)/$B$1)+1 -> 1 | C8: =MOD(A8-1,$B$1)+1 -> 6 | D8: {=INDEX('Linha 02'!$A$4:$A$1000,B8)} -> 20010003 | E8: {=INDEX('Linha 02'!$B$4:$B$1000,B8)} -> Agua Sanitaria Aquafast Cx/04 X 5l | F8: {=INDEX('Linha 02'!$C$3:$Z$3,C8)} -> 20050143 | G8: {=INDEX('Linha 02'!$C$2:$Z$2,C8)} -> Desinfetante Ito Lavanda Cx/04 X 5l | H8: {=INDEX('Linha 02'!$C$4:$ZZ$1000,B8,C8)} -> 0.010416667
A9: 7 | B9: =INT((A9-1)/$B$1)+1 -> 1 | C9: =MOD(A9-1,$B$1)+1 -> 7 | D9: {=INDEX('Linha 02'!$A$4:$A$1000,B9)} -> 20010003 | E9: {=INDEX('Linha 02'!$B$4:$B$1000,B9)} -> Agua Sanitaria Aquafast Cx/04 X 5l | F9: {=INDEX('Linha 02'!$C$3:$Z$3,C9)} -> 20050144 | G9: {=INDEX('Linha 02'!$C$2:$Z$2,C9)} -> Desinfetante Ito Marine Cx/04 X 5l | H9: {=INDEX('Linha 02'!$C$4:$ZZ$1000,B9,C9)} -> 0.010416667
A10: 8 | B10: =INT((A10-1)/$B$1)+1 -> 1 | C10: =MOD(A10-1,$B$1)+1 -> 8 | D10: {=INDEX('Linha 02'!$A$4:$A$1000,B10)} -> 20010003 | E10: {=INDEX('Linha 02'!$B$4:$B$1000,B10)} -> Agua Sanitaria Aquafast Cx/04 X 5l | F10: {=INDEX('Linha 02'!$C$3:$Z$3,C10)} -> 20050158 | G10: {=INDEX('Linha 02'!$C$2:$Z$2,C10)} -> Desinfetante Aquafast Cha Branco Cx/04 X 5l Emb. Econo | H10: {=INDEX('Linha 02'!$C$4:$ZZ$1000,B10,C10)} -> 0.013888889
A11: 9 | B11: =INT((A11-1)/$B$1)+1 -> 1 | C11: =MOD(A11-1,$B$1)+1 -> 9 | D11: {=INDEX('Linha 02'!$A$4:$A$1000,B11)} -> 20010003 | E11: {=INDEX('Linha 02'!$B$4:$B$1000,B11)} -> Agua Sanitaria Aquafast Cx/04 X 5l | F11: {=INDEX('Linha 02'!$C$3:$Z$3,C11)} -> 20160003 | G11: {=INDEX('Linha 02'!$C$2:$Z$2,C11)} -> Alvejante S/ Cloro Aquafast Cx/04 X 5l (Emb Econ) | H11: {=INDEX('Linha 02'!$C$4:$ZZ$1000,B11,C11)} -> 0.0069444444
A12: 10 | B12: =INT((A12-1)/$B$1)+1 -> 1 | C12: =MOD(A12-1,$B$1)+1 -> 10 | D12: {=INDEX('Linha 02'!$A$4:$A$1000,B12)} -> 20010003 | E12: {=INDEX('Linha 02'!$B$4:$B$1000,B12)} -> Agua Sanitaria Aquafast Cx/04 X 5l | F12: {=INDEX('Linha 02'!$C$3:$Z$3,C12)} -> 20160005 | G12: {=INDEX('Linha 02'!$C$2:$Z$2,C12)} -> Alvejante S/ Cloro Aquafast Cx/04 X 3l | H12: {=INDEX('Linha 02'!$C$4:$ZZ$1000,B12,C12)} -> 0.0069444444
A13: 11 | B13: =INT((A13-1)/$B$1)+1 -> 2 | C13: =MOD(A13-1,$B$1)+1 -> 1 | D13: {=INDEX('Linha 02'!$A$4:$A$1000,B13)} -> 20010011 | E13: {=INDEX('Linha 02'!$B$4:$B$1000,B13)} -> Agua Sanitaria Verde Ito Cx/04 X 5l | F13: {=INDEX('Linha 02'!$C$3:$Z$3,C13)} -> 20010003 | G13: {=INDEX('Linha 02'!$C$2:$Z$2,C13)} -> Agua Sanitaria Aquafast Cx/04 X 5l | H13: {=INDEX('Linha 02'!$C$4:$ZZ$1000,B13,C13)} -> 0
A14: 12 | B14: =INT((A14-1)/$B$1)+1 -> 2 | C14: =MOD(A14-1,$B$1)+1 -> 2 | D14: {=INDEX('Linha 02'!$A$4:$A$1000,B14)} -> 20010011 | E14: {=INDEX('Linha 02'!$B$4:$B$1000,B14)} -> Agua Sanitaria Verde Ito Cx/04 X 5l | F14: {=INDEX('Linha 02'!$C$3:$Z$3,C14)} -> 20010011 | G14: {=INDEX('Linha 02'!$C$2:$Z$2,C14)} -> Agua Sanitaria Verde Ito Cx/04 X 5l | H14: {=INDEX('Linha 02'!$C$4:$ZZ$1000,B14,C14)} -> 0
A15: 13 | B15: =INT((A15-1)/$B$1)+1 -> 2 | C15: =MOD(A15-1,$B$1)+1 -> 3 | D15: {=INDEX('Linha 02'!$A$4:$A$1000,B15)} -> 20010011 | E15: {=INDEX('Linha 02'!$B$4:$B$1000,B15)} -> Agua Sanitaria Verde Ito Cx/04 X 5l | F15: {=INDEX('Linha 02'!$C$3:$Z$3,C15)} -> 20050113 | G15: {=INDEX('Linha 02'!$C$2:$Z$2,C15)} -> Desinfetante Aquafast Campos Lavanda Cx/04 5l Emb. Econ | H15: {=INDEX('Linha 02'!$C$4:$ZZ$1000,B15,C15)} -> 0.034722222
... A102: 100 | B102: =INT((A102-1)/$B$1)+1 -> 10 | C102: =MOD(A102-1,$B$1)+1 -> 10 | D102: {=INDEX('Linha 02'!$A$4:$A$1000,B102)} -> 20160005 | E102: {=INDEX('Linha 02'!$B$4:$B$1000,B102)} -> Alvejante S/ Cloro Aquafast Cx/04 X 3l | F102: {=INDEX('Linha 02'!$C$3:$Z$3,C102)} -> 20160005 | G102: {=INDEX('Linha 02'!$C$2:$Z$2,C102)} -> Alvejante S/ Cloro Aquafast Cx/04 X 3l | H102: {=INDEX('Linha 02'!$C$4:$ZZ$1000,B102,C102)} -> 0

Sheet Linha 03
A1: Coluna1 | B1: Coluna2 | C1: Coluna3 | D1: Coluna4 | E1: Coluna5 | F1: Coluna6 | G1: Coluna7 | H1: Coluna8 | I1: Coluna9 | J1: Coluna10 | K1: Coluna11 | L1: Coluna12 | M1: Coluna13 | N1: Coluna14 | O1: Coluna15 | P1: Coluna16 | Q1: Coluna17 | R1: Coluna18 | S1: Coluna19 | T1: Coluna20 | U1: Coluna21 | V1: Coluna22 | W1: Coluna23 | X1: Coluna24 | Y1: Coluna25 | Z1: Coluna26 | AA1: Coluna27 | AB1: Coluna28 | AC1: Coluna29 | AD1: Coluna30 | AE1: Coluna31 | AF1: Coluna32 | AG1: Coluna33 | AH1: Coluna34 | AI1: Coluna35 | AJ1: Coluna36 | AK1: Coluna37 | AL1: Coluna38 | AM1: Coluna39 | AN1: Coluna40 | AO1: Coluna41 | AP1: Coluna42 | AQ1: Coluna43
C2: Amaciante Aquafast Azul Fresc. Manha Cx/06 X 2l | D2: Amaciante Aquafast Rosa Jard. Florid Cx/06 X 2l | E2: Amaciante Aquafast Branco Pura Caric. Cx/06 X 2l | F2: Amaciante Ito Azul Cx/06 X 2l | G2: Amaciante Ito Rosa Cx/06 X 2l | H2: Amaciante Ito Branco Cx/06 X 2l | I2: Amaciante Myata Azul Cx/06 X 2l | J2: Amaciante Myata Rosa Cx/06 X 2l | K2: Amaciante Aquafast Vermelho Seducao Cx C/06 X 2l | L2: Amaciante Aquafast Roxo Magia Cx/06 X 2l | M2: Amaciante Aquafast Energia Cx/06 X 2l | N2: Desinfetante Aquafast Campos Lavanda Cx/06 X 2l | O2: Desinfetante Aquafast Jardim Florido Cx/06 X 2l | P2: Desinfetante Aquafast Marine Cx/06 X 2l | Q2: Desinfetante Ito Lavanda Cx/06 X 2l | R2: Desinfetante Ito Floral Cx/06 X 2l | S2: Desinfetante Ito Eucalipto Cx/06 X 2l | T2: Desinfetante Myata Lavanda Cx/06 X 2l | U2: Desinfetante Myata Floral Cx/06 X 2l | V2: Desinfetante Aquafast Paixao Cx/06 X 2l | W2: Desinfetante Aquafast Harmonia Natural Cx/06 X 2l | X2: Desinfetante Ito Harmonia Natural Cx/06 X 2l | Y2: Desinfetante Myata Harmonia Natural Cx/06 X 2l | Z2: Desinfetante Ito Marine Cx/06 X 2l | AA2: Desinfetante Aquafast Cha Branco Cx/06 X 2l | AB2: Limp Perf Aquafast Magia Seducao Cx/06 X 2l (Promoc) | AC2: Limp Perf Aquafast Frescor Da Manha Cx/06 X 2l (Promoc) | AD2: Limp Perf Aquafast Doce Romance Cx/06 X 2l (Promoc) | AE2: Limp Perf Aquafast Essencia Natural Cx06 X 2l | AF2: Lava Roup. Aquafast Baby Cx/12 X 1l | AG2: Lava Roupas Aquafast Multi Acao Cx/06 X 2l | AH2: Lava Roupas Aquafast Glicerina Cx/06 X 2l | AI2: Lava Roup. Aquafast Multiacao Cx/12 X 1l | AJ2: Lava Roupas Aquafast Ternura Cx/06 X 2l | AK2: Lava Roup. Aquafast Tradicional Cx/12 X 1l | AL2: Lava Roup. Aquafast Flores B. E Baunilha Cx/12 X 1l | AM2: Lava Roupas Aquafast Flores B. E Baunilha Cx/06 X 2l | AN2: Lava Roupas Aquafast Lavagem Rapida Total Clean Cx/12 X 1l | AO2: Lava Roupas Aquafast Lavagem Rapida Fresh Clean Cx/12 X 1l | AP2: Neutralizador De Odores Aquafast Floral Cx/06 X 2l | AQ2: Neutralizador De Odores Aquafast Marine Cx/06 2l
C3: 20040006 | D3: 20040008 | E3: 20040009 | F3: 20040026 | G3: 20040028 | H3: 20040029 | I3: 20040055 | J3: 20040057 | K3: 20040084 | L3: 20040089 | M3: 20040094 | N3: 20050010 | O3: 20050011 | P3: 20050016 | Q3: 20050031 | R3: 20050032 | S3: 20050034 | T3: 20050077 | U3: 20050078 | V3: 20050115 | W3: 20050117 | X3: 20050123 | Y3: 20050124 | Z3: 20050142 | AA3: 20050159 | AB3: 20060007 | AC3: 20060009 | AD3: 20060017 | AE3: 20060028 | AF3: 20200003 | AG3: 20200005 | AH3: 20200006 | AI3: 20200015 | AJ3: 20200036 | AK3: 20200063 | AL3: 20200064 | AM3: 20200065 | AN3: 20200072 | AO3: 20200074 | AP3: 20250005 | AQ3: 20250007
A4: 20040006 | B4: Amaciante Aquafast Azul Fresc. Manha Cx/06 X 2l | C4: 0 | D4: 0.010416667 | E4: 0.010416667 | F4: 0.010416667 | G4: 0.010416667 | H4: 0.010416667 | I4: 0.010416667 | J4: 0.010416667 | K4: 0.010416667 | L4: 0.010416667 | M4: 0.010416667 | N4: 0.010416667 | O4: 0.010416667 | P4: 0.010416667 | Q4: 0.010416667 | R4: 0.010416667 | S4: 0.010416667 | T4: 0.010416667 | U4: 0.010416667 | V4: 0.010416667 | W4: 0.010416667 | X4: 0.010416667 | Y4: 0.010416667 | Z4: 0.010416667 | AA4: 0.013888889
A5: 20040008 | B5: Amaciante Aquafast Rosa Jard. Florid Cx/06 X 2l | C5: 0.0069444444 | D5: 0 | E5: 0.0069444444 | F5: 0.0069444444 | G5: 0.0069444444 | H5: 0.0069444444 | I5: 0.0069444444 | J5: 0.0069444444 | K5: 0.0069444444 | L5: 0.0069444444 | M5: 0.0069444444 | N5: 0.0069444444 | O5: 0.0069444444 | P5: 0.0069444444 | Q5: 0.0069444444 | R5: 0.0069444444 | S5: 0.0069444444 | T5: 0.0069444444 | U5: 0.0069444444 | V5: 0.0069444444 | W5: 0.0069444444 | X5: 0.0069444444 | Y5: 0.0069444444 | Z5: 0.0069444444 | AA5: 0.013888889 | AB5: 0.0069444444 | AC5: 0.0069444444 | AD5: 0.0069444444 | AE5: 0.0069444444 | AF5: 0.0069444444 | AG5: 0.0069444444 | AH5: 0.0069444444 | AI5: 0.0069444444 | AJ5: 0.0069444444 | AK5: 0.0069444444 | AL5: 0.0069444444 | AM5: 0.0069444444 | AN5: 0.0069444444 | AO5: 0.0069444444 | AP5: 0.0069444444 | AQ5: 0.0069444444
A6: 20040009 | B6: Amaciante Aquafast Branco Pura Caric. Cx/06 X 2l | E6: 0 | AA6: 0.013888889
A7: 20040026 | B7: Amaciante Ito Azul Cx/06 X 2l | F7: 0 | AA7: 0.013888889
A8: 20040028 | B8: Amaciante Ito Rosa Cx/06 X 2l | G8: 0 | AA8: 0.013888889
A9: 20040029 | B9: Amaciante Ito Branco Cx/06 X 2l | H9: 0 | AA9: 0.013888889
A10: 20040055 | B10: Amaciante Myata Azul Cx/06 X 2l | I10: 0 | AA10: 0.013888889
A11: 20040057 | B11: Amaciante Myata Rosa Cx/06 X 2l | J11: 0 | AA11: 0.013888889
A12: 20040084 | B12: Amaciante Aquafast Vermelho Seducao Cx C/06 X 2l | D12: 0.010416667 | K12: 0 | AA12: 0.013888889
A13: 20040089 | B13: Amaciante Aquafast Roxo Magia Cx/06 X 2l | L13: 0 | AA13: 0.013888889
A14: 20040094 | B14: Amaciante Aquafast Energia Cx/06 X 2l | M14: 0 | AA14: 0.013888889
A15: 20050010 | B15: Desinfetante Aquafast Campos Lavanda Cx/06 X 2l | N15: 0 | AA15: 0.013888889
A16: 20050011 | B16: Desinfetante Aquafast Jardim Florido Cx/06 X 2l | O16: 0 | AA16: 0.013888889
A17: 20050016 | B17: Desinfetante Aquafast Marine Cx/06 X 2l | P17: 0 | AA17: 0.013888889
A18: 20050031 | B18: Desinfetante Ito Lavanda Cx/06 X 2l | Q18: 0 | AA18: 0.013888889
A19: 20050032 | B19: Desinfetante Ito Floral Cx/06 X 2l | R19: 0 | AA19: 0.013888889
A20: 20050034 | B20: Desinfetante Ito Eucalipto Cx/06 X 2l | S20: 0 | AA20: 0.013888889
A21: 20050077 | B21: Desinfetante Myata Lavanda Cx/06 X 2l | T21: 0 | AA21: 0.013888889
A22: 20050078 | B22: Desinfetante Myata Floral Cx/06 X 2l | U22: 0 | AA22: 0.013888889
A23: 20050115 | B23: Desinfetante Aquafast Paixao Cx/06 X 2l | V23: 0 | AA23: 0.013888889
A24: 20050117 | B24: Desinfetante Aquafast Harmonia Natural Cx/06 X 2l | W24: 0 | AA24: 0.013888889
A25: 20050123 | B25: Desinfetante Ito Harmonia Natural Cx/06 X 2l | X25: 0 | AA25: 0.013888889
A26: 20050124 | B26: Desinfetante Myata Harmonia Natural Cx/06 X 2l | Y26: 0 | AA26: 0.013888889
A27: 20050142 | B27: Desinfetante Ito Marine Cx/06 X 2l | Z27: 0 | AA27: 0.013888889
A28: 20050159 | B28: Desinfetante Aquafast Cha Branco Cx/06 X 2l | AA28: 0
A29: 20060007 | B29: Limp Perf Aquafast Magia Seducao Cx/06 X 2l (Promoc) | AA29: 0.013888889 | AB29: 0
A30: 20060009 | B30: Limp Perf Aquafast Frescor Da Manha Cx/06 X 2l (Promoc) | AA30: 0.013888889 | AC30: 0
A31: 20060017 | B31: Limp Perf Aquafast Doce Romance Cx/06 X 2l (Promoc) | AA31: 0.013888889 | AD31: 0
A32: 20060028 | B32: Limp Perf Aquafast Essencia Natural Cx06 X 2l | AA32: 0.013888889 | AE32: 0
A33: 20200003 | B33: Lava Roup. Aquafast Baby Cx/12 X 1l | AA33: 0.013888889 | AF33: 0
A34: 20200005 | B34: Lava Roupas Aquafast Multi Acao Cx/06 X 2l | AA34: 0.013888889 | AG34: 0
A35: 20200006 | B35: Lava Roupas Aquafast Glicerina Cx/06 X 2l | AA35: 0.013888889 | AH35: 0
A36: 20200015 | B36: Lava Roup. Aquafast Multiacao Cx/12 X 1l | AA36: 0.013888889 | AI36: 0
A37: 20200036 | B37: Lava Roupas Aquafast Ternura Cx/06 X 2l | AA37: 0.013888889 | AJ37: 0
A38: 20200063 | B38: Lava Roup. Aquafast Tradicional Cx/12 X 1l | AA38: 0.013888889 | AK38: 0
A39: 20200064 | B39: Lava Roup. Aquafast Flores B. E Baunilha Cx/12 X 1l | AA39: 0.013888889 | AL39: 0
A40: 20200065 | B40: Lava Roupas Aquafast Flores B. E Baunilha Cx/06 X 2l | AA40: 0.013888889 | AM40: 0
...

Sheet LISTA 03
A1: =COUNTA('Linha 03'!B:B)-1 -> 41 | B1: =COUNTA('Linha 03'!2:2) -> 41 | C1: =A1*B1 -> 1681
A3: {=_xlfn.SEQUENCE($C$1)} -> 1 | B3: =INT((A3-1)/$B$1)+1 -> 1 | C3: =MOD(A3-1,$B$1)+1 -> 1 | D3: {=INDEX('Linha 03'!$A$4:$A$1000,B3)} -> 20040006 | E3: {=INDEX('Linha 03'!$B$4:$B$1000,B3)} -> Amaciante Aquafast Azul Fresc. Manha Cx/06 X 2l | F3: {=INDEX('Linha 03'!$C$3:$ZZ$3,C3)} -> 20040006 | G3: {=INDEX('Linha 03'!$C$2:$ZZ$2,C3)} -> Amaciante Aquafast Azul Fresc. Manha Cx/06 X 2l | H3: {=INDEX('Linha 03'!$C$4:$ZZ$1000,B3,C3)} -> 0
A4: 2 | B4: =INT((A4-1)/$B$1)+1 -> 1 | C4: =MOD(A4-1,$B$1)+1 -> 2 | D4: {=INDEX('Linha 03'!$A$4:$A$1000,B4)} -> 20040006 | E4: {=INDEX('Linha 03'!$B$4:$B$1000,B4)} -> Amaciante Aquafast Azul Fresc. Manha Cx/06 X 2l | F4: {=INDEX('Linha 03'!$C$3:$ZZ$3,C4)} -> 20040008 | G4: {=INDEX('Linha 03'!$C$2:$ZZ$2,C4)} -> Amaciante Aquafast Rosa Jard. Florid Cx/06 X 2l | H4: {=INDEX('Linha 03'!$C$4:$ZZ$1000,B4,C4)} -> 0.010416667
A5: 3 | B5: =INT((A5-1)/$B$1)+1 -> 1 | C5: =MOD(A5-1,$B$1)+1 -> 3 | D5: {=INDEX('Linha 03'!$A$4:$A$1000,B5)} -> 20040006 | E5: {=INDEX('Linha 03'!$B$4:$B$1000,B5)} -> Amaciante Aquafast Azul Fresc. Manha Cx/06 X 2l | F5: {=INDEX('Linha 03'!$C$3:$ZZ$3,C5)} -> 20040009 | G5: {=INDEX('Linha 03'!$C$2:$ZZ$2,C5)} -> Amaciante Aquafast Branco Pura Caric. Cx/06 X 2l | H5: {=INDEX('Linha 03'!$C$4:$ZZ$1000,B5,C5)} -> 0.010416667
A6: 4 | B6: =INT((A6-1)/$B$1)+1 -> 1 | C6: =MOD(A6-1,$B$1)+1 -> 4 | D6: {=INDEX('Linha 03'!$A$4:$A$1000,B6)} -> 20040006 | E6: {=INDEX('Linha 03'!$B$4:$B$1000,B6)} -> Amaciante Aquafast Azul Fresc. Manha Cx/06 X 2l | F6: {=INDEX('Linha 03'!$C$3:$ZZ$3,C6)} -> 20040026 | G6: {=INDEX('Linha 03'!$C$2:$ZZ$2,C6)} -> Amaciante Ito Azul Cx/06 X 2l | H6: {=INDEX('Linha 03'!$C$4:$ZZ$1000,B6,C6)} -> 0.010416667
A7: 5 | B7: =INT((A7-1)/$B$1)+1 -> 1 | C7: =MOD(A7-1,$B$1)+1 -> 5 | D7: {=INDEX('Linha 03'!$A$4:$A$1000,B7)} -> 20040006 | E7: {=INDEX('Linha 03'!$B$4:$B$1000,B7)} -> Amaciante Aquafast Azul Fresc. Manha Cx/06 X 2l | F7: {=INDEX('Linha 03'!$C$3:$ZZ$3,C7)} -> 20040028 | G7: {=INDEX('Linha 03'!$C$2:$ZZ$2,C7)} -> Amaciante Ito Rosa Cx/06 X 2l | H7: {=INDEX('Linha 03'!$C$4:$ZZ$1000,B7,C7)} -> 0.010416667
A8: 6 | B8: =INT((A8-1)/$B$1)+1 -> 1 | C8: =MOD(A8-1,$B$1)+1 -> 6 | D8: {=INDEX('Linha 03'!$A$4:$A$1000,B8)} -> 20040006 | E8: {=INDEX('Linha 03'!$B$4:$B$1000,B8)} -> Amaciante Aquafast Azul Fresc. Manha Cx/06 X 2l | F8: {=INDEX('Linha 03'!$C$3:$ZZ$3,C8)} -> 20040029 | G8: {=INDEX('Linha 03'!$C$2:$ZZ$2,C8)} -> Amaciante Ito Branco Cx/06 X 2l | H8: {=INDEX('Linha 03'!$C$4:$ZZ$1000,B8,C8)} -> 0.010416667
A9: 7 | B9: =INT((A9-1)/$B$1)+1 -> 1 | C9: =MOD(A9-1,$B$1)+1 -> 7 | D9: {=INDEX('Linha 03'!$A$4:$A$1000,B9)} -> 20040006 | E9: {=INDEX('Linha 03'!$B$4:$B$1000,B9)} -> Amaciante Aquafast Azul Fresc. Manha Cx/06 X 2l | F9: {=INDEX('Linha 03'!$C$3:$ZZ$3,C9)} -> 20040055 | G9: {=INDEX('Linha 03'!$C$2:$ZZ$2,C9)} -> Amaciante Myata Azul Cx/06 X 2l | H9: {=INDEX('Linha 03'!$C$4:$ZZ$1000,B9,C9)} -> 0.010416667
A10: 8 | B10: =INT((A10-1)/$B$1)+1 -> 1 | C10: =MOD(A10-1,$B$1)+1 -> 8 | D10: {=INDEX('Linha 03'!$A$4:$A$1000,B10)} -> 20040006 | E10: {=INDEX('Linha 03'!$B$4:$B$1000,B10)} -> Amaciante Aquafast Azul Fresc. Manha Cx/06 X 2l | F10: {=INDEX('Linha 03'!$C$3:$ZZ$3,C10)} -> 20040057 | G10: {=INDEX('Linha 03'!$C$2:$ZZ$2,C10)} -> Amaciante Myata Rosa Cx/06 X 2l | H10: {=INDEX('Linha 03'!$C$4:$ZZ$1000,B10,C10)} -> 0.010416667
A11: 9 | B11: =INT((A11-1)/$B$1)+1 -> 1 | C11: =MOD(A11-1,$B$1)+1 -> 9 | D11: {=INDEX('Linha 03'!$A$4:$A$1000,B11)} -> 20040006 | E11: {=INDEX('Linha 03'!$B$4:$B$1000,B11)} -> Amaciante Aquafast Azul Fresc. Manha Cx/06 X 2l | F11: {=INDEX('Linha 03'!$C$3:$ZZ$3,C11)} -> 20040084 | G11: {=INDEX('Linha 03'!$C$2:$ZZ$2,C11)} -> Amaciante Aquafast Vermelho Seducao Cx C/06 X 2l | H11: {=INDEX('Linha 03'!$C$4:$ZZ$1000,B11,C11)} -> 0.010416667
A12: 10 | B12: =INT((A12-1)/$B$1)+1 -> 1 | C12: =MOD(A12-1,$B$1)+1 -> 10 | D12: {=INDEX('Linha 03'!$A$4:$A$1000,B12)} -> 20040006 | E12: {=INDEX('Linha 03'!$B$4:$B$1000,B12)} -> Amaciante Aquafast Azul Fresc. Manha Cx/06 X 2l | F12: {=INDEX('Linha 03'!$C$3:$ZZ$3,C12)} -> 20040089 | G12: {=INDEX('Linha 03'!$C$2:$ZZ$2,C12)} -> Amaciante Aquafast Roxo Magia Cx/06 X 2l | H12: {=INDEX('Linha 03'!$C$4:$ZZ$1000,B12,C12)} -> 0.010416667
A13: 11 | B13: =INT((A13-1)/$B$1)+1 -> 1 | C13: =MOD(A13-1,$B$1)+1 -> 11 | D13: {=INDEX('Linha 03'!$A$4:$A$1000,B13)} -> 20040006 | E13: {=INDEX('Linha 03'!$B$4:$B$1000,B13)} -> Amaciante Aquafast Azul Fresc. Manha Cx/06 X 2l | F13: {=INDEX('Linha 03'!$C$3:$ZZ$3,C13)} -> 20040094 | G13: {=INDEX('Linha 03'!$C$2:$ZZ$2,C13)} -> Amaciante Aquafast Energia Cx/06 X 2l | H13: {=INDEX('Linha 03'!$C$4:$ZZ$1000,B13,C13)} -> 0.010416667
A14: 12 | B14: =INT((A14-1)/$B$1)+1 -> 1 | C14: =MOD(A14-1,$B$1)+1 -> 12 | D14: {=INDEX('Linha 03'!$A$4:$A$1000,B14)} -> 20040006 | E14: {=INDEX('Linha 03'!$B$4:$B$1000,B14)} -> Amaciante Aquafast Azul Fresc. Manha Cx/06 X 2l | F14: {=INDEX('Linha 03'!$C$3:$ZZ$3,C14)} -> 20050010 | G14: {=INDEX('Linha 03'!$C$2:$ZZ$2,C14)} -> Desinfetante Aquafast Campos Lavanda Cx/06 X 2l | H14: {=INDEX('Linha 03'!$C$4:$ZZ$1000,B14,C14)} -> 0.010416667
A15: 13 | B15: =INT((A15-1)/$B$1)+1 -> 1 | C15: =MOD(A15-1,$B$1)+1 -> 13 | D15: {=INDEX('Linha 03'!$A$4:$A$1000,B15)} -> 20040006 | E15: {=INDEX('Linha 03'!$B$4:$B$1000,B15)} -> Amaciante Aquafast Azul Fresc. Manha Cx/06 X 2l | F15: {=INDEX('Linha 03'!$C$3:$ZZ$3,C15)} -> 20050011 | G15: {=INDEX('Linha 03'!$C$2:$ZZ$2,C15)} -> Desinfetante Aquafast Jardim Florido Cx/06 X 2l | H15: {=INDEX('Linha 03'!$C$4:$ZZ$1000,B15,C15)} -> 0.010416667
... A1683: 1681 | B1683: =INT((A1683-1)/$B$1)+1 -> 41 | C1683: =MOD(A1683-1,$B$1)+1 -> 41 | D1683: {=INDEX('Linha 03'!$A$4:$A$1000,B1683)} -> 20250007 | E1683: {=INDEX('Linha 03'!$B$4:$B$1000,B1683)} -> Neutralizador De Odores Aquafast Marine Cx/06 2l | F1683: {=INDEX('Linha 03'!$C$3:$ZZ$3,C1683)} -> 20250007 | G1683: {=INDEX('Linha 03'!$C$2:$ZZ$2,C1683)} -> Neutralizador De Odores Aquafast Marine Cx/06 2l | H1683: {=INDEX('Linha 03'!$C$4:$ZZ$1000,B1683,C1683)} -> 0

Sheet Linha 04
A1: Coluna1 | B1: Coluna2 | C1: Coluna3 | D1: Coluna4 | E1: Coluna5 | F1: Coluna6 | G1: Coluna7 | H1: Coluna8 | I1: Coluna9 | J1: Coluna10 | K1: Coluna11 | L1: Coluna12 | M1: Coluna13 | N1: Coluna14 | O1: Coluna15 | P1: Coluna16 | Q1: Coluna17 | R1: Coluna18 | S1: Coluna19 | T1: Coluna20 | U1: Coluna21 | V1: Coluna22 | W1: Coluna23 | X1: Coluna24 | Y1: Coluna25 | Z1: Coluna26 | AA1: Coluna27 | AB1: Coluna28 | AC1: Coluna29 | AD1: Coluna30
C2: Detergente Aquafast Maca Cx/24 X 500ml | D2: Detergente Aquafast Limao Cx/24 X 500ml | E2: Detergente Aquafast Neutro Cx/24 X 500ml | F2: Detergente Aquafast Clear Cx/24 X 500ml (Natural) | G2: Detergente Aquafast Maca Cx/12 X 1l | H2: Detergente Aquafast Limao Cx/12 X 1l | I2: Detergente Aquafast Neutro Cx/12 X 1l | J2: Detergente Aquafast Clear Cx/12 X 1l (Natural) | K2: Detergente Ito Maca Cx/24 X 500ml | L2: Detergente Ito Limao Cx/24 X 500ml | M2: Detergente Ito Neutro Cx/24 X 500ml | N2: Detergente Ito Clear Cx/24 X 500ml | O2: Detergente Myata Maca Cx/24 X 500ml | P2: Detergente Myata Limao Cx/24 X 500ml | Q2: Detergente Myata Neutro Cx/24 X 500ml | R2: Detergente Aquafast Coco Cx/24 X 500ml | S2: Desinfetante Aquafast Campos Lavanda Cx/12 X 500ml | T2: Desinfetante Ito Lavanda Cx/12 X 500ml | U2: Desinfetante Aquafast Paixao Cx/12 X 500ml | V2: Desinfetante Aquafast Harmonia Natural Cx/12 X 500ml | W2: Desinfetante Aquafast Campos Lavanda Cx/12 X 1l | X2: Desinfetante Aquafast Marine Cx/12 X 1l | Y2: Desinfetante Aquafast Paixao Cx/12 X 1l | Z2: Desinfetante Aquafast Harmonia Natural Cx/12 X 1l | AA2: Desinfetante Ito Harmonia Natural Cx/12 X 500ml | AB2: Intermed Pack Desinfetante Paixao Cx/12 X 1l | AC2: Intermed Pack Desinfetante Campos Lavanda Cx/12 X 1l | AD2: Intermed Pack Desinfetante Marine Cx/12 X 1l
C3: 20030001 | D3: 20030002 | E3: 20030003 | F3: 20030004 | G3: 20030011 | H3: 20030012 | I3: 20030013 | J3: 20030014 | K3: 20030020 | L3: 20030021 | M3: 20030022 | N3: 20030023 | O3: 20030038 | P3: 20030039 | Q3: 20030040 | R3: 20030067 | S3: 20050001 | T3: 20050026 | U3: 20050119 | V3: 20050145 | W3: 20050149 | X3: 20050150 | Y3: 20050151 | Z3: 20050152 | AA3: 20050153 | AB3: 20050155 | AC3: 20050156 | AD3: 20050157
A4: 20030001 | B4: Detergente Aquafast Maca Cx/24 X 500ml | C4: 0
A5: 20030002 | B5: Detergente Aquafast Limao Cx/24 X 500ml | D5: 0
A6: 20030003 | B6: Detergente Aquafast Neutro Cx/24 X 500ml | E6: 0
A7: 20030004 | B7: Detergente Aquafast Clear Cx/24 X 500ml (Natural) | F7: 0
A8: 20030011 | B8: Detergente Aquafast Maca Cx/12 X 1l | G8: 0
A9: 20030012 | B9: Detergente Aquafast Limao Cx/12 X 1l | H9: 0
A10: 20030013 | B10: Detergente Aquafast Neutro Cx/12 X 1l | I10: 0
A11: 20030014 | B11: Detergente Aquafast Clear Cx/12 X 1l (Natural) | J11: 0
A12: 20030020 | B12: Detergente Ito Maca Cx/24 X 500ml | K12: 0
A13: 20030021 | B13: Detergente Ito Limao Cx/24 X 500ml | L13: 0
A14: 20030022 | B14: Detergente Ito Neutro Cx/24 X 500ml | M14: 0
A15: 20030023 | B15: Detergente Ito Clear Cx/24 X 500ml | N15: 0
A16: 20030038 | B16: Detergente Myata Maca Cx/24 X 500ml | O16: 0
A17: 20030039 | B17: Detergente Myata Limao Cx/24 X 500ml | P17: 0
A18: 20030040 | B18: Detergente Myata Neutro Cx/24 X 500ml | Q18: 0
A19: 20030067 | B19: Detergente Aquafast Coco Cx/24 X 500ml | R19: 0
A20: 20050001 | B20: Desinfetante Aquafast Campos Lavanda Cx/12 X 500ml | S20: 0
A21: 20050026 | B21: Desinfetante Ito Lavanda Cx/12 X 500ml | T21: 0
A22: 20050119 | B22: Desinfetante Aquafast Paixao Cx/12 X 500ml | U22: 0
A23: 20050145 | B23: Desinfetante Aquafast Harmonia Natural Cx/12 X 500ml | V23: 0
A24: 20050149 | B24: Desinfetante Aquafast Campos Lavanda Cx/12 X 1l | W24: 0
A25: 20050150 | B25: Desinfetante Aquafast Marine Cx/12 X 1l | X25: 0
A26: 20050151 | B26: Desinfetante Aquafast Paixao Cx/12 X 1l | Y26: 0
A27: 20050152 | B27: Desinfetante Aquafast Harmonia Natural Cx/12 X 1l | Z27: 0
A28: 20050153 | B28: Desinfetante Ito Harmonia Natural Cx/12 X 500ml | AA28: 0
A29: 20050155 | B29: Intermed Pack Desinfetante Paixao Cx/12 X 1l | AB29: 0
A30: 20050156 | B30: Intermed Pack Desinfetante Campos Lavanda Cx/12 X 1l | AC30: 0
A31: 20050157 | B31: Intermed Pack Desinfetante Marine Cx/12 X 1l | AD31: 0

Sheet LISTA 04
A1: =COUNTA('Linha 04'!B:B)-1 -> 28 | B1: =COUNTA('Linha 04'!2:2) -> 28 | C1: =A1*B1 -> 784
A3: {=_xlfn.SEQUENCE($C$1)} -> 1 | B3: =INT((A3-1)/$B$1)+1 -> 1 | C3: =MOD(A3-1,$B$1)+1 -> 1 | D3: {=INDEX('Linha 04'!$A$4:$A$1000,B3)} -> 20030001 | E3: {=INDEX('Linha 04'!$B$4:$B$1000,B3)} -> Detergente Aquafast Maca Cx/24 X 500ml | F3: {=INDEX('Linha 04'!$C$3:$ZZ$3,C3)} -> 20030001 | G3: {=INDEX('Linha 04'!$C$2:$ZZ$2,C3)} -> Detergente Aquafast Maca Cx/24 X 500ml | H3: {=INDEX('Linha 04'!$C$4:$ZZ$1000,B3,C3)} -> 0
A4: 2 | B4: =INT((A4-1)/$B$1)+1 -> 1 | C4: =MOD(A4-1,$B$1)+1 -> 2 | D4: {=INDEX('Linha 04'!$A$4:$A$1000,B4)} -> 20030001 | E4: {=INDEX('Linha 04'!$B$4:$B$1000,B4)} -> Detergente Aquafast Maca Cx/24 X 500ml | F4: {=INDEX('Linha 04'!$C$3:$ZZ$3,C4)} -> 20030002 | G4: {=INDEX('Linha 04'!$C$2:$ZZ$2,C4)} -> Detergente Aquafast Limao Cx/24 X 500ml | H4: {=INDEX('Linha 04'!$C$4:$ZZ$1000,B4,C4)} -> 0
A5: 3 | B5: =INT((A5-1)/$B$1)+1 -> 1 | C5: =MOD(A5-1,$B$1)+1 -> 3 | D5: {=INDEX('Linha 04'!$A$4:$A$1000,B5)} -> 20030001 | E5: {=INDEX('Linha 04'!$B$4:$B$1000,B5)} -> Detergente Aquafast Maca Cx/24 X 500ml | F5: {=INDEX('Linha 04'!$C$3:$ZZ$3,C5)} -> 20030003 | G5: {=INDEX('Linha 04'!$C$2:$ZZ$2,C5)} -> Detergente Aquafast Neutro Cx/24 X 500ml | H5: {=INDEX('Linha 04'!$C$4:$ZZ$1000,B5,C5)} -> 0
A6: 4 | B6: =INT((A6-1)/$B$1)+1 -> 1 | C6: =MOD(A6-1,$B$1)+1 -> 4 | D6: {=INDEX('Linha 04'!$A$4:$A$1000,B6)} -> 20030001 | E6: {=INDEX('Linha 04'!$B$4:$B$1000,B6)} -> Detergente Aquafast Maca Cx/24 X 500ml | F6: {=INDEX('Linha 04'!$C$3:$ZZ$3,C6)} -> 20030004 | G6: {=INDEX('Linha 04'!$C$2:$ZZ$2,C6)} -> Detergente Aquafast Clear Cx/24 X 500ml (Natural) | H6: {=INDEX('Linha 04'!$C$4:$ZZ$1000,B6,C6)} -> 0
A7: 5 | B7: =INT((A7-1)/$B$1)+1 -> 1 | C7: =MOD(A7-1,$B$1)+1 -> 5 | D7: {=INDEX('Linha 04'!$A$4:$A$1000,B7)} -> 20030001 | E7: {=INDEX('Linha 04'!$B$4:$B$1000,B7)} -> Detergente Aquafast Maca Cx/24 X 500ml | F7: {=INDEX('Linha 04'!$C$3:$ZZ$3,C7)} -> 20030011 | G7: {=INDEX('Linha 04'!$C$2:$ZZ$2,C7)} -> Detergente Aquafast Maca Cx/12 X 1l | H7: {=INDEX('Linha 04'!$C$4:$ZZ$1000,B7,C7)} -> 0
A8: 6 | B8: =INT((A8-1)/$B$1)+1 -> 1 | C8: =MOD(A8-1,$B$1)+1 -> 6 | D8: {=INDEX('Linha 04'!$A$4:$A$1000,B8)} -> 20030001 | E8: {=INDEX('Linha 04'!$B$4:$B$1000,B8)} -> Detergente Aquafast Maca Cx/24 X 500ml | F8: {=INDEX('Linha 04'!$C$3:$ZZ$3,C8)} -> 20030012 | G8: {=INDEX('Linha 04'!$C$2:$ZZ$2,C8)} -> Detergente Aquafast Limao Cx/12 X 1l | H8: {=INDEX('Linha 04'!$C$4:$ZZ$1000,B8,C8)} -> 0
A9: 7 | B9: =INT((A9-1)/$B$1)+1 -> 1 | C9: =MOD(A9-1,$B$1)+1 -> 7 | D9: {=INDEX('Linha 04'!$A$4:$A$1000,B9)} -> 20030001 | E9: {=INDEX('Linha 04'!$B$4:$B$1000,B9)} -> Detergente Aquafast Maca Cx/24 X 500ml | F9: {=INDEX('Linha 04'!$C$3:$ZZ$3,C9)} -> 20030013 | G9: {=INDEX('Linha 04'!$C$2:$ZZ$2,C9)} -> Detergente Aquafast Neutro Cx/12 X 1l | H9: {=INDEX('Linha 04'!$C$4:$ZZ$1000,B9,C9)} -> 0
A10: 8 | B10: =INT((A10-1)/$B$1)+1 -> 1 | C10: =MOD(A10-1,$B$1)+1 -> 8 | D10: {=INDEX('Linha 04'!$A$4:$A$1000,B10)} -> 20030001 | E10: {=INDEX('Linha 04'!$B$4:$B$1000,B10)} -> Detergente Aquafast Maca Cx/24 X 500ml | F10: {=INDEX('Linha 04'!$C$3:$ZZ$3,C10)} -> 20030014 | G10: {=INDEX('Linha 04'!$C$2:$ZZ$2,C10)} -> Detergente Aquafast Clear Cx/12 X 1l (Natural) | H10: {=INDEX('Linha 04'!$C$4:$ZZ$1000,B10,C10)} -> 0
A11: 9 | B11: =INT((A11-1)/$B$1)+1 -> 1 | C11: =MOD(A11-1,$B$1)+1 -> 9 | D11: {=INDEX('Linha 04'!$A$4:$A$1000,B11)} -> 20030001 | E11: {=INDEX('Linha 04'!$B$4:$B$1000,B11)} -> Detergente Aquafast Maca Cx/24 X 500ml | F11: {=INDEX('Linha 04'!$C$3:$ZZ$3,C11)} -> 20030020 | G11: {=INDEX('Linha 04'!$C$2:$ZZ$2,C11)} -> Detergente Ito Maca Cx/24 X 500ml | H11: {=INDEX('Linha 04'!$C$4:$ZZ$1000,B11,C11)} -> 0
A12: 10 | B12: =INT((A12-1)/$B$1)+1 -> 1 | C12: =MOD(A12-1,$B$1)+1 -> 10 | D12: {=INDEX('Linha 04'!$A$4:$A$1000,B12)} -> 20030001 | E12: {=INDEX('Linha 04'!$B$4:$B$1000,B12)} -> Detergente Aquafast Maca Cx/24 X 500ml | F12: {=INDEX('Linha 04'!$C$3:$ZZ$3,C12)} -> 20030021 | G12: {=INDEX('Linha 04'!$C$2:$ZZ$2,C12)} -> Detergente Ito Limao Cx/24 X 500ml | H12: {=INDEX('Linha 04'!$C$4:$ZZ$1000,B12,C12)} -> 0
A13: 11 | B13: =INT((A13-1)/$B$1)+1 -> 1 | C13: =MOD(A13-1,$B$1)+1 -> 11 | D13: {=INDEX('Linha 04'!$A$4:$A$1000,B13)} -> 20030001 | E13: {=INDEX('Linha 04'!$B$4:$B$1000,B13)} -> Detergente Aquafast Maca Cx/24 X 500ml | F13: {=INDEX('Linha 04'!$C$3:$ZZ$3,C13)} -> 20030022 | G13: {=INDEX('Linha 04'!$C$2:$ZZ$2,C13)} -> Detergente Ito Neutro Cx/24 X 500ml | H13: {=INDEX('Linha 04'!$C$4:$ZZ$1000,B13,C13)} -> 0
A14: 12 | B14: =INT((A14-1)/$B$1)+1 -> 1 | C14: =MOD(A14-1,$B$1)+1 -> 12 | D14: {=INDEX('Linha 04'!$A$4:$A$1000,B14)} -> 20030001 | E14: {=INDEX('Linha 04'!$B$4:$B$1000,B14)} -> Detergente Aquafast Maca Cx/24 X 500ml | F14: {=INDEX('Linha 04'!$C$3:$ZZ$3,C14)} -> 20030023 | G14: {=INDEX('Linha 04'!$C$2:$ZZ$2,C14)} -> Detergente Ito Clear Cx/24 X 500ml | H14: {=INDEX('Linha 04'!$C$4:$ZZ$1000,B14,C14)} -> 0
A15: 13 | B15: =INT((A15-1)/$B$1)+1 -> 1 | C15: =MOD(A15-1,$B$1)+1 -> 13 | D15: {=INDEX('Linha 04'!$A$4:$A$1000,B15)} -> 20030001 | E15: {=INDEX('Linha 04'!$B$4:$B$1000,B15)} -> Detergente Aquafast Maca Cx/24 X 500ml | F15: {=INDEX('Linha 04'!$C$3:$ZZ$3,C15)} -> 20030038 | G15: {=INDEX('Linha 04'!$C$2:$ZZ$2,C15)} -> Detergente Myata Maca Cx/24 X 500ml | H15: {=INDEX('Linha 04'!$C$4:$ZZ$1000,B15,C15)} -> 0
... A786: 784 | B786: =INT((A786-1)/$B$1)+1 -> 28 | C786: =MOD(A786-1,$B$1)+1 -> 28 | D786: {=INDEX('Linha 04'!$A$4:$A$1000,B786)} -> 20050157 | E786: {=INDEX('Linha 04'!$B$4:$B$1000,B786)} -> Intermed Pack Desinfetante Marine Cx/12 X 1l | F786: {=INDEX('Linha 04'!$C$3:$ZZ$3,C786)} -> 20050157 | G786: {=INDEX('Linha 04'!$C$2:$ZZ$2,C786)} -> Intermed Pack Desinfetante Marine Cx/12 X 1l | H786: {=INDEX('Linha 04'!$C$4:$ZZ$1000,B786,C786)} -> 0

Sheet Linha 05
A1: Coluna1 | B1: Coluna2 | C1: Coluna3 | D1: Coluna4 | E1: Coluna5 | F1: Coluna6 | G1: Coluna7 | H1: Coluna8 | I1: Coluna9 | J1: Coluna10 | K1: Coluna11 | L1: Coluna12 | M1: Coluna13 | N1: Coluna14 | O1: Coluna15 | P1: Coluna16 | Q1: Coluna17 | R1: Coluna18 | S1: Coluna19 | T1: Coluna20 | U1: Coluna21 | V1: Coluna22 | W1: Coluna23
C2: Detergente Aquafast Limao Cx/04 X 5l (Emb Econ) | D2: Detergente Aquafast Neutro Cx/04 X 5l (Emb Econ) | E2: Detergente Aquafast Clear Cx/04 X 5l (Emb Econ) | F2: Detergente Ito Neutro Cx/04 X 5l | G2: Detergente Ito Clear Cx/04 X 5l | H2: Amaciante Ito Azul Cx/04 X 5l | I2: Amaciante Aquafast Azul Cx C/04 X 5l (Fresc Manh) Emb. Econ | J2: Amaciante Aquafast Rosa Cx C/04 X 5l (Jard Flor) Emb. Econ | K2: Amaciante Aquafast Vermelho Cx/04 X 5l (Seducao) Emb. Econ | L2: Amaciante Aquafast Roxo Cx/04 X 5l (Magia) Emb. Econ | M2: Amaciante Aquafast Energia Cx/04 X 5l Emb. Econ | N2: Amac. Conc. Aquafast Branco Ternura Cx/ 04 X 3l | O2: Amac. Conc. Aquafast Azul Harmonia Cx/ 04 X 3l | P2: Lava Roupas Aquafast Multi Acao Cx/04 X 5l (Emb Econ) | Q2: Lava Roupas Aquafast Glicerina Cx/04 X 5l | R2: Lava Roupas Aquafast Glicerina Cx/04 X 3l | S2: Lava Roupas Aquafast Multiacao Cx/04 X 3l | T2: Lava Roupas Aquafast Ternura Cx/04 X 3l | U2: Lava Roupas Aquafast Ternura C/04 X 5l (Emb Econ) | V2: Lava Roupas Aquafast Flores Brancas E Baunilha Cx/4 X 3l | W2: Lava Roupas Aquafast Alta Performance 7l
C3: 20030008 | D3: 20030009 | E3: 20030010 | F3: 20030024 | G3: 20030083 | H3: 20040030 | I3: 20040074 | J3: 20040075 | K3: 20040086 | L3: 20040091 | M3: 20040095 | N3: 20150028 | O3: 20150051 | P3: 20200009 | Q3: 20200014 | R3: 20200020 | S3: 20200022 | T3: 20200026 | U3: 20200027 | V3: 20200058 | W3: 20200077
A4: 20030008 | B4: Detergente Aquafast Limao Cx/04 X 5l (Emb Econ) | C4: 0 | D4: 0.0069444444 | E4: 0.0069444444 | F4: 0.0069444444 | G4: 0.0069444444 | H4: 0.013888889 | I4: 0.013888889 | J4: 0.013888889 | K4: 0.013888889 | L4: 0.013888889 | M4: 0.013888889 | N4: 0.034722222 | O4: 0.034722222 | P4: 0.013888889 | Q4: 0.013888889 | R4: 0.034722222 | S4: 0.034722222 | T4: 0.034722222 | U4: 0.013888889 | V4: 0.034722222 | W4: 0.034722222
A5: 20030009 | B5: Detergente Aquafast Neutro Cx/04 X 5l (Emb Econ) | C5: 0.0069444444 | D5: 0 | E5: 0.0069444444 | F5: 0.0069444444 | G5: 0.0069444444 | H5: 0.013888889 | I5: 0.013888889 | J5: 0.013888889 | K5: 0.013888889 | L5: 0.013888889 | M5: 0.013888889 | N5: 0.034722222 | O5: 0.034722222 | P5: 0.013888889 | Q5: 0.013888889 | R5: 0.034722222 | S5: 0.034722222 | T5: 0.034722222 | U5: 0.013888889 | V5: 0.034722222 | W5: 0.034722222
A6: 20030010 | B6: Detergente Aquafast Clear Cx/04 X 5l (Emb Econ) | C6: 0.0069444444 | D6: 0.0069444444 | E6: 0 | F6: 0.0069444444 | G6: 0.0069444444 | H6: 0.013888889 | I6: 0.013888889 | J6: 0.013888889 | K6: 0.013888889 | L6: 0.013888889 | M6: 0.013888889 | N6: 0.034722222 | O6: 0.034722222 | P6: 0.013888889 | Q6: 0.013888889 | R6: 0.034722222 | S6: 0.034722222 | T6: 0.034722222 | U6: 0.013888889 | V6: 0.034722222 | W6: 0.034722222
A7: 20030024 | B7: Detergente Ito Neutro Cx/04 X 5l | C7: 0.0069444444 | D7: 0.0069444444 | E7: 0.0069444444 | F7: 0 | G7: 0.0069444444 | H7: 0.013888889 | I7: 0.013888889 | J7: 0.013888889 | K7: 0.013888889 | L7: 0.013888889 | M7: 0.013888889 | N7: 0.034722222 | O7: 0.034722222 | P7: 0.013888889 | Q7: 0.013888889 | R7: 0.034722222 | S7: 0.034722222 | T7: 0.034722222 | U7: 0.013888889 | V7: 0.034722222 | W7: 0.034722222
A8: 20030083 | B8: Detergente Ito Clear Cx/04 X 5l | C8: 0.0069444444 | D8: 0.0069444444 | E8: 0.0069444444 | F8: 0.0069444444 | G8: 0 | H8: 0.013888889 | I8: 0.013888889 | J8: 0.013888889 | K8: 0.013888889 | L8: 0.013888889 | M8: 0.013888889 | N8: 0.034722222 | O8: 0.034722222 | P8: 0.013888889 | Q8: 0.013888889 | R8: 0.034722222 | S8: 0.034722222 | T8: 0.034722222 | U8: 0.013888889 | V8: 0.034722222 | W8: 0.034722222
A9: 20040030 | B9: Amaciante Ito Azul Cx/04 X 5l | C9: 0.013888889 | D9: 0.013888889 | E9: 0.013888889 | F9: 0.013888889 | G9: 0.013888889 | H9: 0 | I9: 0.0069444444 | J9: 0.0069444444 | K9: 0.0069444444 | L9: 0.0069444444 | M9: 0.0069444444 | N9: 0.034722222 | O9: 0.034722222 | P9: 0.013888889 | Q9: 0.013888889 | R9: 0.034722222 | S9: 0.034722222 | T9: 0.034722222 | U9: 0.013888889 | V9: 0.034722222 | W9: 0.034722222
A10: 20040074 | B10: Amaciante Aquafast Azul Cx C/04 X 5l (Fresc Manh) Emb. Econ | C10: 0.013888889 | D10: 0.013888889 | E10: 0.013888889 | F10: 0.013888889 | G10: 0.013888889 | H10: 0.0069444444 | I10: 0 | J10: 0.0069444444 | K10: 0.0069444444 | L10: 0.0069444444 | M10: 0.0069444444 | N10: 0.034722222 | O10: 0.034722222 | P10: 0.013888889 | Q10: 0.013888889 | R10: 0.034722222 | S10: 0.034722222 | T10: 0.034722222 | U10: 0.013888889 | V10: 0.034722222 | W10: 0.034722222
A11: 20040075 | B11: Amaciante Aquafast Rosa Cx C/04 X 5l (Jard Flor) Emb. Econ | C11: 0.013888889 | D11: 0.013888889 | E11: 0.013888889 | F11: 0.013888889 | G11: 0.013888889 | H11: 0.0069444444 | I11: 0.0069444444 | J11: 0 | K11: 0.0069444444 | L11: 0.0069444444 | M11: 0.0069444444 | N11: 0.034722222 | O11: 0.034722222 | P11: 0.013888889 | Q11: 0.013888889 | R11: 0.034722222 | S11: 0.034722222 | T11: 0.034722222 | U11: 0.013888889 | V11: 0.034722222 | W11: 0.034722222
A12: 20040086 | B12: Amaciante Aquafast Vermelho Cx/04 X 5l (Seducao) Emb. Econ | C12: 0.013888889 | D12: 0.013888889 | E12: 0.013888889 | F12: 0.013888889 | G12: 0.013888889 | H12: 0.0069444444 | I12: 0.0069444444 | J12: 0.0069444444 | K12: 0 | L12: 0.0069444444 | M12: 0.0069444444 | N12: 0.034722222 | O12: 0.034722222 | P12: 0.013888889 | Q12: 0.013888889 | R12: 0.034722222 | S12: 0.034722222 | T12: 0.034722222 | U12: 0.013888889 | V12: 0.034722222 | W12: 0.034722222
A13: 20040091 | B13: Amaciante Aquafast Roxo Cx/04 X 5l (Magia) Emb. Econ | C13: 0.013888889 | D13: 0.013888889 | E13: 0.013888889 | F13: 0.013888889 | G13: 0.013888889 | H13: 0.0069444444 | I13: 0.0069444444 | J13: 0.0069444444 | K13: 0.0069444444 | L13: 0 | M13: 0.0069444444 | N13: 0.034722222 | O13: 0.034722222 | P13: 0.013888889 | Q13: 0.013888889 | R13: 0.034722222 | S13: 0.034722222 | T13: 0.034722222 | U13: 0.013888889 | V13: 0.034722222 | W13: 0.034722222
A14: 20040095 | B14: Amaciante Aquafast Energia Cx/04 X 5l Emb. Econ | C14: 0.013888889 | D14: 0.013888889 | E14: 0.013888889 | F14: 0.013888889 | G14: 0.013888889 | H14: 0.0069444444 | I14: 0.0069444444 | J14: 0.0069444444 | K14: 0.0069444444 | L14: 0.0069444444 | M14: 0 | N14: 0.034722222 | O14: 0.034722222 | P14: 0.013888889 | Q14: 0.013888889 | R14: 0.034722222 | S14: 0.034722222 | T14: 0.034722222 | U14: 0.013888889 | V14: 0.034722222 | W14: 0.034722222
A15: 20150028 | B15: Amac. Conc. Aquafast Branco Ternura Cx/ 04 X 3l | C15: 0.034722222 | D15: 0.034722222 | E15: 0.034722222 | F15: 0.034722222 | G15: 0.034722222 | H15: 0.034722222 | I15: 0.034722222 | J15: 0.034722222 | K15: 0.034722222 | L15: 0.034722222 | M15: 0.034722222 | N15: 0 | O15: 0.0069444444 | P15: 0.034722222 | Q15: 0.034722222 | R15: 0.013888889 | S15: 0.013888889 | T15: 0.013888889 | U15: 0.034722222 | V15: 0.013888889 | W15: 0.034722222
... A20: 20200022 | B20: Lava Roupas Aquafast Multiacao Cx/04 X 3l | C20: 0.034722222 | D20: 0.034722222 | E20: 0.034722222 | F20: 0.034722222 | G20: 0.034722222 | H20: 0.034722222 | I20: 0.034722222 | J20: 0.034722222 | K20: 0.034722222 | L20: 0.034722222 | M20: 0.034722222 | N20: 0.013888889 | O20: 0.013888889 | P20: 0.034722222 | Q20: 0.034722222 | R20: 0.0069444444 | S20: 0 | T20: 0.0069444444 | U20: 0.034722222 | V20: 0.0069444444 | W20: 0.034722222
A21: 20200026 | B21: Lava Roupas Aquafast Ternura Cx/04 X 3l | C21: 0.034722222 | D21: 0.034722222 | E21: 0.034722222 | F21: 0.034722222 | G21: 0.034722222 | H21: 0.034722222 | I21: 0.034722222 | J21: 0.034722222 | K21: 0.034722222 | L21: 0.034722222 | M21: 0.034722222 | N21: 0.013888889 | O21: 0.013888889 | P21: 0.034722222 | Q21: 0.034722222 | R21: 0.0069444444 | S21: 0.0069444444 | T21: 0
A22: 20200027 | B22: Lava Roupas Aquafast Ternura C/04 X 5l (Emb Econ) | C22: 0.013888889 | D22: 0.013888889 | E22: 0.013888889 | F22: 0.013888889 | G22: 0.013888889 | H22: 0.013888889 | I22: 0.013888889 | J22: 0.013888889 | K22: 0.013888889 | L22: 0.013888889 | M22: 0.013888889 | N22: 0.034722222 | O22: 0.034722222 | P22: 0.0069444444 | Q22: 0.0069444444 | R22: 0.034722222 | S22: 0.034722222 | T22: 0.034722222 | U22: 0 | V22: 0.034722222 | W22: 0.034722222
A23: 20200058 | B23: Lava Roupas Aquafast Flores Brancas E Baunilha Cx/4 X 3l | C23: 0.034722222 | D23: 0.034722222 | E23: 0.034722222 | F23: 0.034722222 | G23: 0.034722222 | H23: 0.034722222 | I23: 0.034722222 | J23: 0.034722222 | K23: 0.034722222 | L23: 0.034722222 | M23: 0.034722222 | N23: 0.013888889 | O23: 0.013888889 | P23: 0.034722222 | Q23: 0.034722222 | R23: 0.0069444444 | S23: 0.0069444444 | T23: 0.0069444444 | U23: 0.034722222 | V23: 0 | W23: 0.034722222
A24: 20200077 | B24: Lava Roupas Aquafast Alta Performance 7l | C24: 0.034722222 | D24: 0.034722222 | E24: 0.034722222 | F24: 0.034722222 | G24: 0.034722222 | H24: 0.034722222 | I24: 0.034722222 | J24: 0.034722222 | K24: 0.034722222 | L24: 0.034722222 | M24: 0.034722222 | N24: 0.034722222 | O24: 0.034722222 | P24: 0.034722222 | Q24: 0.034722222 | R24: 0.034722222 | S24: 0.034722222 | T24: 0.034722222 | U24: 0.034722222 | V24: 0.034722222 | W24: 0

Sheet LISTA 05
A1: =COUNTA('Linha 05'!B:B)-1 -> 21 | B1: =COUNTA('Linha 05'!2:2) -> 21 | C1: =A1*B1 -> 441
A3: {=_xlfn.SEQUENCE($C$1)} -> 1 | B3: =INT((A3-1)/$B$1)+1 -> 1 | C3: =MOD(A3-1,$B$1)+1 -> 1 | D3: {=INDEX('Linha 05'!$A$4:$A$1000,B3)} -> 20030008 | E3: {=INDEX('Linha 05'!$B$4:$B$1000,B3)} -> Detergente Aquafast Limao Cx/04 X 5l (Emb Econ) | F3: {=INDEX('Linha 05'!$C$3:$ZZ$3,C3)} -> 20030008 | G3: {=INDEX('Linha 05'!$C$2:$ZZ$2,C3)} -> Detergente Aquafast Limao Cx/04 X 5l (Emb Econ) | H3: {=INDEX('Linha 05'!$C$4:$ZZ$1000,B3,C3)} -> 0 | I3: =CONCATENATE(D3," ",F3) -> 20030008 20030008 | J3: 0
A4: 2 | B4: =INT((A4-1)/$B$1)+1 -> 1 | C4: =MOD(A4-1,$B$1)+1 -> 2 | D4: {=INDEX('Linha 05'!$A$4:$A$1000,B4)} -> 20030008 | E4: {=INDEX('Linha 05'!$B$4:$B$1000,B4)} -> Detergente Aquafast Limao Cx/04 X 5l (Emb Econ) | F4: {=INDEX('Linha 05'!$C$3:$ZZ$3,C4)} -> 20030009 | G4: {=INDEX('Linha 05'!$C$2:$ZZ$2,C4)} -> Detergente Aquafast Neutro Cx/04 X 5l (Emb Econ) | H4: {=INDEX('Linha 05'!$C$4:$ZZ$1000,B4,C4)} -> 0.0069444444 | I4: =CONCATENATE(D4," ",F4) -> 20030008 20030009 | J4: 0.0069444444
A5: 3 | B5: =INT((A5-1)/$B$1)+1 -> 1 | C5: =MOD(A5-1,$B$1)+1 -> 3 | D5: {=INDEX('Linha 05'!$A$4:$A$1000,B5)} -> 20030008 | E5: {=INDEX('Linha 05'!$B$4:$B$1000,B5)} -> Detergente Aquafast Limao Cx/04 X 5l (Emb Econ) | F5: {=INDEX('Linha 05'!$C$3:$ZZ$3,C5)} -> 20030010 | G5: {=INDEX('Linha 05'!$C$2:$ZZ$2,C5)} -> Detergente Aquafast Clear Cx/04 X 5l (Emb Econ) | H5: {=INDEX('Linha 05'!$C$4:$ZZ$1000,B5,C5)} -> 0.0069444444 | I5: =CONCATENATE(D5," ",F5) -> 20030008 20030010 | J5: 0.0069444444
A6: 4 | B6: =INT((A6-1)/$B$1)+1 -> 1 | C6: =MOD(A6-1,$B$1)+1 -> 4 | D6: {=INDEX('Linha 05'!$A$4:$A$1000,B6)} -> 20030008 | E6: {=INDEX('Linha 05'!$B$4:$B$1000,B6)} -> Detergente Aquafast Limao Cx/04 X 5l (Emb Econ) | F6: {=INDEX('Linha 05'!$C$3:$ZZ$3,C6)} -> 20030024 | G6: {=INDEX('Linha 05'!$C$2:$ZZ$2,C6)} -> Detergente Ito Neutro Cx/04 X 5l | H6: {=INDEX('Linha 05'!$C$4:$ZZ$1000,B6,C6)} -> 0.0069444444 | I6: =CONCATENATE(D6," ",F6) -> 20030008 20030024 | J6: 0.0069444444
A7: 5 | B7: =INT((A7-1)/$B$1)+1 -> 1 | C7: =MOD(A7-1,$B$1)+1 -> 5 | D7: {=INDEX('Linha 05'!$A$4:$A$1000,B7)} -> 20030008 | E7: {=INDEX('Linha 05'!$B$4:$B$1000,B7)} -> Detergente Aquafast Limao Cx/04 X 5l (Emb Econ) | F7: {=INDEX('Linha 05'!$C$3:$ZZ$3,C7)} -> 20030083 | G7: {=INDEX('Linha 05'!$C$2:$ZZ$2,C7)} -> Detergente Ito Clear Cx/04 X 5l | H7: {=INDEX('Linha 05'!$C$4:$ZZ$1000,B7,C7)} -> 0.0069444444 | I7: =CONCATENATE(D7," ",F7) -> 20030008 20030083 | J7: 0.0069444444
A8: 6 | B8: =INT((A8-1)/$B$1)+1 -> 1 | C8: =MOD(A8-1,$B$1)+1 -> 6 | D8: {=INDEX('Linha 05'!$A$4:$A$1000,B8)} -> 20030008 | E8: {=INDEX('Linha 05'!$B$4:$B$1000,B8)} -> Detergente Aquafast Limao Cx/04 X 5l (Emb Econ) | F8: {=INDEX('Linha 05'!$C$3:$ZZ$3,C8)} -> 20040030 | G8: {=INDEX('Linha 05'!$C$2:$ZZ$2,C8)} -> Amaciante Ito Azul Cx/04 X 5l | H8: {=INDEX('Linha 05'!$C$4:$ZZ$1000,B8,C8)} -> 0.013888889 | I8: =CONCATENATE(D8," ",F8) -> 20030008 20040030 | J8: 0.013888889
A9: 7 | B9: =INT((A9-1)/$B$1)+1 -> 1 | C9: =MOD(A9-1,$B$1)+1 -> 7 | D9: {=INDEX('Linha 05'!$A$4:$A$1000,B9)} -> 20030008 | E9: {=INDEX('Linha 05'!$B$4:$B$1000,B9)} -> Detergente Aquafast Limao Cx/04 X 5l (Emb Econ) | F9: {=INDEX('Linha 05'!$C$3:$ZZ$3,C9)} -> 20040074 | G9: {=INDEX('Linha 05'!$C$2:$ZZ$2,C9)} -> Amaciante Aquafast Azul Cx C/04 X 5l (Fresc Manh) Emb. Econ | H9: {=INDEX('Linha 05'!$C$4:$ZZ$1000,B9,C9)} -> 0.013888889 | I9: =CONCATENATE(D9," ",F9) -> 20030008 20040074 | J9: 0.013888889
A10: 8 | B10: =INT((A10-1)/$B$1)+1 -> 1 | C10: =MOD(A10-1,$B$1)+1 -> 8 | D10: {=INDEX('Linha 05'!$A$4:$A$1000,B10)} -> 20030008 | E10: {=INDEX('Linha 05'!$B$4:$B$1000,B10)} -> Detergente Aquafast Limao Cx/04 X 5l (Emb Econ) | F10: {=INDEX('Linha 05'!$C$3:$ZZ$3,C10)} -> 20040075 | G10: {=INDEX('Linha 05'!$C$2:$ZZ$2,C10)} -> Amaciante Aquafast Rosa Cx C/04 X 5l (Jard Flor) Emb. Econ | H10: {=INDEX('Linha 05'!$C$4:$ZZ$1000,B10,C10)} -> 0.013888889 | I10: =CONCATENATE(D10," ",F10) -> 20030008 20040075 | J10: 0.013888889
A11: 9 | B11: =INT((A11-1)/$B$1)+1 -> 1 | C11: =MOD(A11-1,$B$1)+1 -> 9 | D11: {=INDEX('Linha 05'!$A$4:$A$1000,B11)} -> 20030008 | E11: {=INDEX('Linha 05'!$B$4:$B$1000,B11)} -> Detergente Aquafast Limao Cx/04 X 5l (Emb Econ) | F11: {=INDEX('Linha 05'!$C$3:$ZZ$3,C11)} -> 20040086 | G11: {=INDEX('Linha 05'!$C$2:$ZZ$2,C11)} -> Amaciante Aquafast Vermelho Cx/04 X 5l (Seducao) Emb. Econ | H11: {=INDEX('Linha 05'!$C$4:$ZZ$1000,B11,C11)} -> 0.013888889 | I11: =CONCATENATE(D11," ",F11) -> 20030008 20040086 | J11: 0.013888889
A12: 10 | B12: =INT((A12-1)/$B$1)+1 -> 1 | C12: =MOD(A12-1,$B$1)+1 -> 10 | D12: {=INDEX('Linha 05'!$A$4:$A$1000,B12)} -> 20030008 | E12: {=INDEX('Linha 05'!$B$4:$B$1000,B12)} -> Detergente Aquafast Limao Cx/04 X 5l (Emb Econ) | F12: {=INDEX('Linha 05'!$C$3:$ZZ$3,C12)} -> 20040091 | G12: {=INDEX('Linha 05'!$C$2:$ZZ$2,C12)} -> Amaciante Aquafast Roxo Cx/04 X 5l (Magia) Emb. Econ | H12: {=INDEX('Linha 05'!$C$4:$ZZ$1000,B12,C12)} -> 0.013888889 | I12: =CONCATENATE(D12," ",F12) -> 20030008 20040091 | J12: 0.013888889
A13: 11 | B13: =INT((A13-1)/$B$1)+1 -> 1 | C13: =MOD(A13-1,$B$1)+1 -> 11 | D13: {=INDEX('Linha 05'!$A$4:$A$1000,B13)} -> 20030008 | E13: {=INDEX('Linha 05'!$B$4:$B$1000,B13)} -> Detergente Aquafast Limao Cx/04 X 5l (Emb Econ) | F13: {=INDEX('Linha 05'!$C$3:$ZZ$3,C13)} -> 20040095 | G13: {=INDEX('Linha 05'!$C$2:$ZZ$2,C13)} -> Amaciante Aquafast Energia Cx/04 X 5l Emb. Econ | H13: {=INDEX('Linha 05'!$C$4:$ZZ$1000,B13,C13)} -> 0.013888889 | I13: =CONCATENATE(D13," ",F13) -> 20030008 20040095 | J13: 0.013888889
A14: 12 | B14: =INT((A14-1)/$B$1)+1 -> 1 | C14: =MOD(A14-1,$B$1)+1 -> 12 | D14: {=INDEX('Linha 05'!$A$4:$A$1000,B14)} -> 20030008 | E14: {=INDEX('Linha 05'!$B$4:$B$1000,B14)} -> Detergente Aquafast Limao Cx/04 X 5l (Emb Econ) | F14: {=INDEX('Linha 05'!$C$3:$ZZ$3,C14)} -> 20150028 | G14: {=INDEX('Linha 05'!$C$2:$ZZ$2,C14)} -> Amac. Conc. Aquafast Branco Ternura Cx/ 04 X 3l | H14: {=INDEX('Linha 05'!$C$4:$ZZ$1000,B14,C14)} -> 0.034722222 | I14: =CONCATENATE(D14," ",F14) -> 20030008 20150028 | J14: 0.034722222
A15: 13 | B15: =INT((A15-1)/$B$1)+1 -> 1 | C15: =MOD(A15-1,$B$1)+1 -> 13 | D15: {=INDEX('Linha 05'!$A$4:$A$1000,B15)} -> 20030008 | E15: {=INDEX('Linha 05'!$B$4:$B$1000,B15)} -> Detergente Aquafast Limao Cx/04 X 5l (Emb Econ) | F15: {=INDEX('Linha 05'!$C$3:$ZZ$3,C15)} -> 20150051 | G15: {=INDEX('Linha 05'!$C$2:$ZZ$2,C15)} -> Amac. Conc. Aquafast Azul Harmonia Cx/ 04 X 3l | H15: {=INDEX('Linha 05'!$C$4:$ZZ$1000,B15,C15)} -> 0.034722222 | I15: =CONCATENATE(D15," ",F15) -> 20030008 20150051 | J15: 0.034722222
... A443: 441 | B443: =INT((A443-1)/$B$1)+1 -> 21 | C443: =MOD(A443-1,$B$1)+1 -> 21 | D443: {=INDEX('Linha 05'!$A$4:$A$1000,B443)} -> 20200077 | E443: {=INDEX('Linha 05'!$B$4:$B$1000,B443)} -> Lava Roupas Aquafast Alta Performance 7l | F443: {=INDEX('Linha 05'!$C$3:$ZZ$3,C443)} -> 20200077 | G443: {=INDEX('Linha 05'!$C$2:$ZZ$2,C443)} -> Lava Roupas Aquafast Alta Performance 7l | H443: {=INDEX('Linha 05'!$C$4:$ZZ$1000,B443,C443)} -> 0 | I443: =CONCATENATE(D443," ",F443) -> 20200077 20200077 | J443: 0

Sheet Linha 06
A1: Coluna1 | B1: Coluna2 | C1: Coluna3 | D1: Coluna4 | E1: Coluna5 | F1: Coluna6 | G1: Coluna7 | H1: Coluna8 | I1: Coluna9 | J1: Coluna10 | K1: Coluna11 | L1: Coluna12 | M1: Coluna13 | N1: Coluna14 | O1: Coluna15 | P1: Coluna16 | Q1: Coluna17 | R1: Coluna18 | S1: Coluna19 | T1: Coluna20 | U1: Coluna21 | V1: Coluna22 | W1: Coluna23 | X1: Coluna24 | Y1: Coluna25 | Z1: Coluna26 | AA1: Coluna27 | AB1: Coluna28 | AC1: Coluna29 | AD1: Coluna30 | AE1: Coluna31 | AF1: Coluna32 | AG1: Coluna33 | AH1: Coluna34 | AI1: Coluna35 | AJ1: Coluna36 | AK1: Coluna37 | AL1: Coluna38 | AM1: Coluna39 | AN1: Coluna40
